Workbook

Sheet DES'25
B1: KSP. NATA BUANA PASUNDAN | I1: INDEKS KETERANGAN WARNA
B2: KOLEKTIBILITAS Bank KB Indonesia X NATA | H2: 1 | K2: FAS KREDIT LEBIH DARI 1 | N2: 3 | Q2: TOPUP / REHAB
B3: Periode : DESEMBER 2025 | H3: 2 | K3: LUNAS / PELUNASAN | N3: 4 | Q3: RESTRUKTUR
N4: 5 | Q4: MD - MENINGGAL DUNIA
B6: NO. | C6: NOPEN | D6: NOREK | E6: TANGGAL | F6: NAMA | G6: MO | H6: PLAFOND | I6: BUNGA | J6: angsuran_ke | K6: tenor | L6: % byr | M6: BAKI AWAL | N6: ANGSURAN JATUH TEMPO | R6: ANGSURAN BELUM DITERIMA | V6: ANGSURAN TELAH DITERIMA | Z6: BAKI AKHIR
N7: POKOK | O7: BUNGA | P7: S.WJB | Q7: JUMLAH | R7: POKOK | S7: BUNGA | T7: S.WJB | U7: JUMLAH | V7: POKOK | W7: BUNGA | X7: S.WJB | Y7: JUMLAH
B8: 1 | E8: 45474 | F8: CUCU TRISNA RAHAYU | G8: RATIH | H8: 0 | J8: 24 | K8: 24 | L8: =J8/K8 -> 1 | M8: 0 | N8: 0 | O8: 0 | Q8: =+N8+O8 -> 0 | R8: 0 | S8: 0 | U8: =+R8+S8 -> 0 | V8: 0 | W8: 0 | Y8: =+V8+W8 -> 0 | Z8: 3 Oktober 2024
B9: 2 | E9: 45475 | F9: ONO SUHANA | G9: HARIS | H9: 0 | J9: 24 | K9: 24 | L9: =J9/K9 -> 1 | M9: 0 | N9: 0 | O9: 0 | Q9: =+N9+O9 -> 0 | R9: 0 | S9: 0 | U9: =+R9+S9 -> 0 | V9: 0 | W9: 0 | Y9: =+V9+W9 -> 0 | Z9: 24 Oktober 2024
B10: 3 | E10: 45446 | F10: APID | G10: AYU | H10: 0 | J10: 24 | K10: 24 | L10: =J10/K10 -> 1 | M10: 0 | N10: 0 | O10: 0 | Q10: =+N10+O10 -> 0 | R10: 0 | S10: 0 | U10: =+R10+S10 -> 0 | V10: 0 | W10: 0 | Y10: =+V10+W10 -> 0 | Z10: 01 November 2024
B11: 4 | E11: 45506 | F11: YANTO SUHARTO | G11: AYU | H11: 0 | J11: 24 | K11: 24 | L11: =J11/K11 -> 1 | M11: 0 | N11: 0 | O11: 0 | Q11: =+N11+O11 -> 0 | R11: 0 | S11: 0 | U11: =+R11+S11 -> 0 | V11: 0 | W11: 0 | Y11: =+V11+W11 -> 0 | Z11: 05 November 2024
B12: 5 | E12: 45539 | F12: SURIP SURYA GUNAWAN | G12: RIKA | H12: 0 | J12: 24 | K12: 24 | L12: =J12/K12 -> 1 | M12: 0 | N12: 0 | O12: 0 | Q12: =+N12+O12 -> 0 | R12: 0 | S12: 0 | U12: =+R12+S12 -> 0 | V12: 0 | W12: 0 | Y12: =+V12+W12 -> 0 | Z12: 07 November 2024
B13: 6 | E13: 45545 | F13: SUMARTINI | G13: VIVI / DITO | H13: 0 | J13: 24 | K13: 24 | L13: =J13/K13 -> 1 | M13: 0 | N13: 0 | O13: 0 | Q13: =+N13+O13 -> 0 | R13: 0 | S13: 0 | U13: =+R13+S13 -> 0 | V13: 0 | W13: 0 | Y13: =+V13+W13 -> 0 | Z13: 14 November 2024
B14: 7 | E14: 45425 | F14: ENCEP IDAM HOLID | G14: AYU | H14: 0 | J14: 24 | K14: 24 | L14: =J14/K14 -> 1 | M14: 0 | N14: 0 | O14: 0 | Q14: =+N14+O14 -> 0 | R14: 0 | S14: 0 | U14: =+R14+S14 -> 0 | V14: 0 | W14: 0 | Y14: =+V14+W14 -> 0 | Z14: 22 November 2024
B15: 8 | E15: 45509 | F15: MAMAN DASMAN | G15: RATIH | H15: 0 | J15: 24 | K15: 24 | L15: =J15/K15 -> 1 | M15: 0 | N15: 0 | O15: 0 | Q15: =+N15+O15 -> 0 | R15: 0 | S15: 0 | U15: =+R15+S15 -> 0 | V15: 0 | W15: 0 | Y15: =+V15+W15 -> 0 | Z15: 12 Desember 2024
B16: 9 | E16: 45506 | F16: SADIAH | G16: IWANUDIN | H16: 0 | J16: 24 | K16: 24 | L16: =J16/K16 -> 1 | M16: 0 | N16: 0 | O16: 0 | Q16: =+N16+O16 -> 0 | R16: 0 | S16: 0 | U16: =+R16+S16 -> 0 | V16: 0 | W16: 0 | Y16: =+V16+W16 -> 0 | Z16: 17 Januari 2025
B17: 10 | E17: 45614 | F17: SULASTRI | G17: RATIH | H17: 0 | J17: 24 | K17: 24 | L17: =J17/K17 -> 1 | M17: 0 | N17: 0 | O17: 0 | Q17: =+N17+O17 -> 0 | R17: 0 | S17: 0 | U17: =+R17+S17 -> 0 | V17: 0 | W17: 0 | Y17: 0 | Z17: 24 Januari 2025
B18: 11 | E18: 45630 | F18: EMAN SULAEMAN - 13116514600 | G18: DIFA/CUCU | H18: 0 | J18: 24 | K18: 24 | L18: =J18/K18 -> 1 | M18: 0 | N18: 0 | O18: 0 | Q18: =+N18+O18 -> 0 | R18: 0 | S18: 0 | U18: =+R18+S18 -> 0 | V18: 0 | W18: 0 | Y18: =+V18+W18 -> 0 | Z18: 04 Februari 2025
B19: 12 | E19: 45448 | F19: EEN JAENAH | G19: RIKA | H19: 0 | J19: 24 | K19: 24 | L19: =J19/K19 -> 1 | M19: 0 | N19: 0 | O19: 0 | Q19: =+N19+O19 -> 0 | R19: 0 | S19: 0 | U19: =+R19+S19 -> 0 | V19: 0 | W19: 0 | Y19: =+V19+W19 -> 0 | Z19: 13 Februari 2025
B20: 13 | E20: 45488 | F20: YAYAH HELIAWATY | G20: HARIS | H20: 0 | J20: 24 | K20: 24 | L20: =J20/K20 -> 1 | M20: 0 | N20: 0 | O20: 0 | Q20: =+N20+O20 -> 0 | R20: 0 | S20: 0 | U20: =+R20+S20 -> 0 | V20: 0 | W20: 0 | Y20: =+V20+W20 -> 0 | Z20: 13 Februari 2025
B21: 14 | E21: 45538 | F21: TITIN RUSTITI | G21: RATIH | H21: 0 | J21: 24 | K21: 24 | L21: =J21/K21 -> 1 | M21: 0 | N21: 0 | O21: 0 | Q21: =+N21+O21 -> 0 | R21: 0 | S21: 0 | U21: =+R21+S21 -> 0 | V21: 0 | W21: 0 | Y21: =+V21+W21 -> 0 | Z21: 18 Februari 2025
B22: 15 | E22: 45548 | F22: SUMARNO | G22: AGUS | H22: 0 | J22: 24 | K22: 24 | L22: =J22/K22 -> 1 | M22: 0 | N22: 0 | O22: 0 | Q22: =+N22+O22 -> 0 | R22: 0 | S22: 0 | U22: =+R22+S22 -> 0 | V22: 0 | W22: 0 | Y22: =+V22+W22 -> 0 | Z22: 21 Februari 2025
B23: 16 | E23: 45481 | F23: EDI SUYADI | G23: DIFA/CUCU | H23: 0 | J23: 24 | K23: 24 | L23: =J23/K23 -> 1 | M23: 0 | N23: 0 | O23: 0 | Q23: =+N23+O23 -> 0 | R23: 0 | S23: 0 | U23: =+R23+S23 -> 0 | V23: 0 | W23: 0 | Y23: =+V23+W23 -> 0 | Z23: 20 Februari 2025
B24: 17 | C24: 20041105433 | E24: 45601 | F24: ENDANG SUPARMAN | G24: RIKA | H24: 0 | J24: 24 | K24: 24 | L24: =J24/K24 -> 1 | M24: 0 | N24: 0 | O24: 0 | Q24: =+N24+O24 -> 0 | R24: 0 | S24: 0 | U24: =+R24+S24 -> 0 | V24: 0 | W24: 0 | Y24: =+V24+W24 -> 0 | Z24: 05 Maret 2025
B25: 18 | C25: ED335755111030 | E25: 45645 | F25: MARDIYANTO WALIMAN | G25: RIKA | H25: 0 | J25: 36 | K25: 36 | L25: =J25/K25 -> 1 | M25: 0 | N25: 0 | O25: 0 | Q25: =+N25+O25 -> 0 | R25: 0 | S25: 0 | U25: =+R25+S25 -> 0 | V25: 0 | W25: 0 | Y25: =+V25+W25 -> 0 | Z25: 12 Maret 2025
B26: 19 | E26: 45516 | F26: SUSILAWATI | G26: RATIH | H26: 0 | J26: 24 | K26: 24 | L26: =J26/K26 -> 1 | M26: 0 | N26: 0 | O26: 0 | Q26: =+N26+O26 -> 0 | R26: 0 | S26: 0 | U26: =+R26+S26 -> 0 | V26: 0 | W26: 0 | Y26: =+V26+W26 -> 0 | Z26: 27 Maret 2025
B27: 20 | E27: 45663 | F27: IKIN SODIKIN | G27: RIKA | H27: 0 | J27: 36 | K27: 36 | L27: =J27/K27 -> 1 | M27: 0 | N27: 0 | O27: 0 | Q27: =+N27+O27 -> 0 | R27: 0 | S27: 0 | U27: =+R27+S27 -> 0 | V27: 0 | W27: 0 | Y27: =+V27+W27 -> 0 | Z27: 22 April 2025
B28: 21 | E28: 45617 | F28: IMAS SUMARSIH | G28: DIFA/HARIS | H28: 0 | J28: 24 | K28: 24 | L28: =J28/K28 -> 1 | M28: 0 | N28: 0 | O28: 0 | Q28: =+N28+O28 -> 0 | R28: 0 | S28: 0 | U28: =+R28+S28 -> 0 | V28: 0 | W28: 0 | Y28: =+V28+W28 -> 0 | Z28: 08 Mei 2025
B29: 22 | E29: 45597 | F29: ASEP YUHENDI | G29: AYU | H29: 0 | J29: 24 | K29: 24 | L29: =J29/K29 -> 1 | M29: 0 | N29: 0 | O29: 0 | Q29: =+N29+O29 -> 0 | U29: =+R29+S29 -> 0 | V29: 0 | W29: 0 | Y29: =+V29+W29 -> 0 | Z29: 05 Mei 2025
B30: 23 | E30: 45425 | F30: EMAN SULAEMAN | G30: AYU | H30: 0 | J30: 12 | K30: 12 | L30: =J30/K30 -> 1 | M30: 0 | N30: 0 | O30: =SUM(H30*2.5/100) -> 0 | Q30: =+N30+O30 -> 0 | R30: 0 | S30: 0 | U30: =+R30+S30 -> 0 | Y30: =+V30+W30 -> 0 | Z30: 01 MEI 2025
B31: 24 | C31: 48005894300 | E31: 45708 | F31: JUNARIAH | G31: AAN | H31: 0 | J31: 24 | K31: 24 | L31: =J31/K31 -> 1 | N31: 0 | O31: 0 | Q31: =+N31+O31 -> 0 | R31: 0 | S31: 0 | U31: =+R31+S31 -> 0 | V31: 0 | W31: 0 | Y31: =+V31+W31 -> 0 | Z31: 14 Mei 2025
B32: 25 | E32: 45448 | F32: EMI SUNARTI | G32: AYU | H32: 0 | J32: 24 | K32: 24 | L32: =J32/K32 -> 1 | M32: 0 | N32: 0 | O32: 0 | Q32: =+N32+O32 -> 0 | R32: 0 | S32: 0 | U32: =+R32+S32 -> 0 | V32: 0 | W32: 0 | Y32: =+V32+W32 -> 0 | Z32: 23 Juni 2025
B33: 26 | E33: 45495 | F33: EMAH SUEMAH | G33: HARIS | H33: 0 | J33: 24 | K33: 24 | L33: =J33/K33 -> 1 | M33: 0 | N33: 0 | O33: 0 | Q33: =+N33+O33 -> 0 | R33: 0 | S33: 0 | U33: =+R33+S33 -> 0 | V33: 0 | W33: 0 | Y33: =+V33+W33 -> 0 | Z33: 05 JUNI 2025
B34: 27 | C34: 13020068900 | E34: 37473 | F34: SUMIATI - 13020068900 | G34: AYU | H34: 0 | J34: 24 | K34: 24 | L34: =J34/K34 -> 1 | M34: 0 | N34: 0 | O34: 0 | Q34: =+N34+O34 -> 0 | R34: 0 | S34: 0 | U34: =+R34+S34 -> 0 | V34: 0 | W34: 0 | Y34: =+V34+W34 -> 0 | Z34: 08 JULI 2025
B35: 28 | E35: 45519 | F35: SOEMARNO B TISNASASMITA | G35: HARIS | H35: 0 | J35: 24 | K35: 24 | L35: =J35/K35 -> 1 | M35: 0 | N35: 0 | O35: 0 | Q35: =+N35+O35 -> 0 | R35: 0 | S35: 0 | U35: =+R35+S35 -> 0 | V35: 0 | W35: 0 | Y35: =+V35+W35 -> 0 | Z35: 11 JULI 2025
B36: 29 | E36: 45525 | F36: BAMBANG SUYONO | G36: HARIS | H36: 0 | J36: 24 | K36: 24 | L36: =J36/K36 -> 1 | M36: 0 | N36: 0 | O36: 0 | Q36: =+N36+O36 -> 0 | R36: 0 | S36: 0 | U36: =+R36+S36 -> 0 | V36: 0 | W36: 0 | Y36: =+V36+W36 -> 0 | Z36: 11 JULI 2025
B37: 30 | E37: 45566 | F37: ENDANG SUARNA | G37: RONA | H37: 0 | J37: 24 | K37: 24 | L37: =J37/K37 -> 1 | M37: 0 | N37: 0 | O37: 0 | Q37: =+N37+O37 -> 0 | R37: 0 | S37: 0 | U37: =+R37+S37 -> 0 | V37: 0 | W37: 0 | Y37: =+V37+W37 -> 0 | Z37: 14 JULI 2025
B38: 31 | E38: 45572 | F38: UCE JUARIAH | G38: ANNISA | H38: 0 | J38: 24 | K38: 24 | L38: =J38/K38 -> 1 | M38: 0 | N38: 0 | O38: 0 | Q38: =+N38+O38 -> 0 | R38: 0 | S38: 0 | U38: =+R38+S38 -> 0 | V38: 0 | W38: 0 | Y38: =+V38+W38 -> 0 | Z38: 10 JULI 2025
B39: 32 | C39: 13041195400 | E39: 45698 | F39: DIDI SUPENO | G39: RATIH | H39: 0 | J39: 36 | K39: 36 | L39: =J39/K39 -> 1 | M39: 0 | N39: 0 | O39: 0 | Q39: =+N39+O39 -> 0 | R39: 0 | S39: 0 | U39: =+R39+S39 -> 0 | V39: 0 | W39: 0 | Y39: =+V39+W39 -> 0 | Z39: 15 JULI 2025
B40: 33 | C40: 48010587700 | E40: 45695 | F40: TOTO KARNOTO | G40: NANANG | H40: 0 | J40: 36 | K40: 36 | L40: =J40/K40 -> 1 | M40: 0 | N40: 0 | O40: 0 | P40: 0 | Q40: 0 | R40: 0 | S40: 0 | T40: 0 | U40: =+R40+S40 -> 0 | V40: 0 | W40: 0 | Y40: =+V40+W40 -> 0 | Z40: 19 AGUSTUS 2025
B41: 34 | E41: 45456 | F41: OMA SUTISNA | G41: AYU | H41: 0 | J41: 24 | K41: 24 | L41: =J41/K41 -> 1 | M41: 0 | N41: 0 | O41: 0 | P41: 0 | Q41: 0 | R41: 0 | S41: 0 | T41: 0 | U41: =+R41+S41 -> 0 | V41: 0 | W41: 0 | Y41: =+V41+W41 -> 0 | Z41: 26 AGUSTUS 2025
...
